Workbook

Sheet Sheet_1
A3: Row Labels | B3: Sum of Товарооборот, руб | C3: Count of Товарооборот на склад
A4: 23 | B4: 1.3603238e+08
A5: Волгоград | B5: 5800290
A6: Екатеринбург | B6: 6829921.5
A7: Казань | B7: 3865251
A8: Кемерово | B8: 2945035.5
A9: Краснодар | B9: 2538967.5
A10: Москва Восток | B10: 18914194
A11: Москва Запад | B11: 19465372
A12: Нижний Новгород | B12: 3013512
A13: Новосибирск | B13: 1293219
A14: Пермь | B14: 1526608.5
A15: Ростов-на-Дону | B15: 1565632.5
A16: Самара | B16: 636345
... A23: Grand Total | B23: 1.3603238e+08

Sheet Ответ
A1: Territory | B1: Товарооборот, руб | C1: Доля Товарооборот, руб | E1: Territory | F1: Товарооборот, руб | G1: Доля в товароборот на склад
A2: Санкт-Петербург Север | B2: 37257840 | C2: =B2 / SUM($B$2:$B$19) -> 0.2738895 | E2: Москва Восток | F2: 350262.86 | G2: =F2 / SUM($F$2:$F$19) -> 0.12904848
A3: Санкт-Петербург Юг | B3: 27770092 | C3: =B3 / SUM($B$2:$B$19) -> 0.20414326 | E3: Москва Запад | F3: 329921.57 | G3: =F3 / SUM($F$2:$F$19) -> 0.12155407
A4: Москва Запад | B4: 19465372 | C4: =B4 / SUM($B$2:$B$19) -> 0.14309367 | E4: Санкт-Петербург Север | F4: 302909.27 | G4: =F4 / SUM($F$2:$F$19) -> 0.11160184
A5: Москва Восток | B5: 18914194 | C5: =B5 / SUM($B$2:$B$19) -> 0.13904186 | E5: Екатеринбург | F5: 220320.05 | G5: =F5 / SUM($F$2:$F$19) -> 0.081173229
A6: Екатеринбург | B6: 6829921.5 | C6: =B6 / SUM($B$2:$B$19) -> 0.050208058 | E6: Санкт-Петербург Юг | F6: 216953.85 | G6: =F6 / SUM($F$2:$F$19) -> 0.079933009
A7: Волгоград | B7: 5800290 | C7: =B7 / SUM($B$2:$B$19) -> 0.04263904 | E7: Казань | F7: 168054.39 | G7: =F7 / SUM($F$2:$F$19) -> 0.061916824
A8: Казань | B8: 3865251 | C8: =B8 / SUM($B$2:$B$19) -> 0.028414199 | E8: Волгоград | F8: 156764.59 | G8: =F8 / SUM($F$2:$F$19) -> 0.057757287
A9: Нижний Новгород | B9: 3013512 | C9: =B9 / SUM($B$2:$B$19) -> 0.022152903 | E9: Нижний Новгород | F9: 150675.6 | G9: =F9 / SUM($F$2:$F$19) -> 0.055513899
A10: Кемерово | B10: 2945035.5 | C10: =B10 / SUM($B$2:$B$19) -> 0.021649519 | E10: Кемерово | F10: 140239.79 | G10: =F10 / SUM($F$2:$F$19) -> 0.051668998
A11: Краснодар | B11: 2538967.5 | C11: =B11 / SUM($B$2:$B$19) -> 0.018664435 | E11: Краснодар | F11: 120903.21 | G11: =F11 / SUM($F$2:$F$19) -> 0.044544763
A12: Ростов-на-Дону | B12: 1565632.5 | C12: =B12 / SUM($B$2:$B$19) -> 0.011509264 | E12: Тюмень | F12: 114635.36 | G12: =F12 / SUM($F$2:$F$19) -> 0.042235476
A13: Пермь | B13: 1526608.5 | C13: =B13 / SUM($B$2:$B$19) -> 0.011222391 | E13: Тольятти | F13: 100774.2 | G13: =F13 / SUM($F$2:$F$19) -> 0.037128565
... A19: Томск | B19: 389013 | C19: =B19 / SUM($B$2:$B$19) -> 0.0028597089 | E19: Новосибирск | F19: 0 | G19: =F19 / SUM($F$2:$F$19) -> 0

Sheet Sheet1
A1: Дата | B1: Территория | C1: Товарооборот, шт | D1: Товарооборот, руб | E1: Количество складов | F1: Количество заказов | G1: Количество клиентов | H1: Товарооборот на склад | I1: Неделя
A2: 43982 | B2: Самара | C2: 7944 | D2: 623971.5 | E2: =IFERROR(VLOOKUP(J2,Sheet2!C2:F505,2),0) -> 15 | F2: =IFERROR(VLOOKUP(J2,Sheet2!C2:F505,3),0) -> 441 | G2: =IFERROR(VLOOKUP(J2, Sheet2!C2:F505,4),0) -> 368 | H2: =IF(VALUE(E2)>0, D2/VALUE(E2), 0) -> 41598.1 | I2: =_xlfn.ISOWEEKNUM(A2) -> 22 | J2: =TEXT(A2,"yyyy-mm-dd") & TRIM(B2) -> 2020-05-31Самара
A3: 43981 | B3: Самара | C3: 10029 | D3: 787101 | E3: =IFERROR(VLOOKUP(J3,Sheet2!C3:F506,2),0) -> 15 | F3: =IFERROR(VLOOKUP(J3,Sheet2!C3:F506,3),0) -> 490 | G3: =IFERROR(VLOOKUP(J3, Sheet2!C3:F506,4),0) -> 409 | H3: =IF(VALUE(E3)>0, D3/VALUE(E3), 0) -> 52473.4 | I3: =_xlfn.ISOWEEKNUM(A3) -> 22 | J3: =TEXT(A3,"yyyy-mm-dd") & TRIM(B3) -> 2020-05-30Самара
A4: 43979 | B4: Самара | C4: 8536.5 | D4: 643944 | E4: =IFERROR(VLOOKUP(J4,Sheet2!C4:F507,2),0) -> 15 | F4: =IFERROR(VLOOKUP(J4,Sheet2!C4:F507,3),0) -> 464 | G4: =IFERROR(VLOOKUP(J4, Sheet2!C4:F507,4),0) -> 390 | H4: =IF(VALUE(E4)>0, D4/VALUE(E4), 0) -> 42929.6 | I4: =_xlfn.ISOWEEKNUM(A4) -> 22 | J4: =TEXT(A4,"yyyy-mm-dd") & TRIM(B4) -> 2020-05-28Самара
A5: 43967 | B5: Кемерово | C5: 38947.5 | D5: 3395892 | E5: =IFERROR(VLOOKUP(J5,Sheet2!C5:F508,2),0) -> 21 | F5: =IFERROR(VLOOKUP(J5,Sheet2!C5:F508,3),0) -> 2145 | G5: =IFERROR(VLOOKUP(J5, Sheet2!C5:F508,4),0) -> 1947 | H5: =IF(VALUE(E5)>0, D5/VALUE(E5), 0) -> 161709.14 | I5: =_xlfn.ISOWEEKNUM(A5) -> 20 | J5: =TEXT(A5,"yyyy-mm-dd") & TRIM(B5) -> 2020-05-16Кемерово
A6: 43970 | B6: Кемерово | C6: 31842 | D6: 2771116.5 | E6: =IFERROR(VLOOKUP(J6,Sheet2!C6:F509,2),0) -> 21 | F6: =IFERROR(VLOOKUP(J6,Sheet2!C6:F509,3),0) -> 1860 | G6: =IFERROR(VLOOKUP(J6, Sheet2!C6:F509,4),0) -> 1704 | H6: =IF(VALUE(E6)>0, D6/VALUE(E6), 0) -> 131957.93 | I6: =_xlfn.ISOWEEKNUM(A6) -> 21 | J6: =TEXT(A6,"yyyy-mm-dd") & TRIM(B6) -> 2020-05-19Кемерово
A7: 43968 | B7: Кемерово | C7: 32023.5 | D7: 2882458.5 | E7: =IFERROR(VLOOKUP(J7,Sheet2!C7:F510,2),0) -> 21 | F7: =IFERROR(VLOOKUP(J7,Sheet2!C7:F510,3),0) -> 1874 | G7: =IFERROR(VLOOKUP(J7, Sheet2!C7:F510,4),0) -> 1705 | H7: =IF(VALUE(E7)>0, D7/VALUE(E7), 0) -> 137259.93 | I7: =_xlfn.ISOWEEKNUM(A7) -> 20 | J7: =TEXT(A7,"yyyy-mm-dd") & TRIM(B7) -> 2020-05-17Кемерово
A8: 43960 | B8: Кемерово | C8: 31147.5 | D8: 2831019 | E8: =IFERROR(VLOOKUP(J8,Sheet2!C8:F511,2),0) -> 21 | F8: =IFERROR(VLOOKUP(J8,Sheet2!C8:F511,3),0) -> 1735 | G8: =IFERROR(VLOOKUP(J8, Sheet2!C8:F511,4),0) -> 1568 | H8: =IF(VALUE(E8)>0, D8/VALUE(E8), 0) -> 134810.43 | I8: =_xlfn.ISOWEEKNUM(A8) -> 19 | J8: =TEXT(A8,"yyyy-mm-dd") & TRIM(B8) -> 2020-05-09Кемерово
A9: 43955 | B9: Кемерово | C9: 25566 | D9: 2372310 | E9: =IFERROR(VLOOKUP(J9,Sheet2!C9:F512,2),0) -> 20 | F9: =IFERROR(VLOOKUP(J9,Sheet2!C9:F512,3),0) -> 1519 | G9: =IFERROR(VLOOKUP(J9, Sheet2!C9:F512,4),0) -> 1372 | H9: =IF(VALUE(E9)>0, D9/VALUE(E9), 0) -> 118615.5 | I9: =_xlfn.ISOWEEKNUM(A9) -> 19 | J9: =TEXT(A9,"yyyy-mm-dd") & TRIM(B9) -> 2020-05-04Кемерово
A10: 43950 | B10: Кемерово | C10: 29319 | D10: 2623480.5 | E10: =IFERROR(VLOOKUP(J10,Sheet2!C10:F513,2),0) -> 18 | F10: =IFERROR(VLOOKUP(J10,Sheet2!C10:F513,3),0) -> 1684 | G10: =IFERROR(VLOOKUP(J10, Sheet2!C10:F513,4),0) -> 1528 | H10: =IF(VALUE(E10)>0, D10/VALUE(E10), 0) -> 145748.92 | I10: =_xlfn.ISOWEEKNUM(A10) -> 18 | J10: =TEXT(A10,"yyyy-mm-dd") & TRIM(B10) -> 2020-04-29Кемерово
A11: 43953 | B11: Кемерово | C11: 29031 | D11: 2711247 | E11: =IFERROR(VLOOKUP(J11,Sheet2!C11:F514,2),0) -> 18 | F11: =IFERROR(VLOOKUP(J11,Sheet2!C11:F514,3),0) -> 1708 | G11: =IFERROR(VLOOKUP(J11, Sheet2!C11:F514,4),0) -> 1534 | H11: =IF(VALUE(E11)>0, D11/VALUE(E11), 0) -> 150624.83 | I11: =_xlfn.ISOWEEKNUM(A11) -> 18 | J11: =TEXT(A11,"yyyy-mm-dd") & TRIM(B11) -> 2020-05-02Кемерово
A12: 43977 | B12: Кемерово | C12: 33423 | D12: 2970330 | E12: =IFERROR(VLOOKUP(J12,Sheet2!C12:F515,2),0) -> 20 | F12: =IFERROR(VLOOKUP(J12,Sheet2!C12:F515,3),0) -> 2044 | G12: =IFERROR(VLOOKUP(J12, Sheet2!C12:F515,4),0) -> 1863 | H12: =IF(VALUE(E12)>0, D12/VALUE(E12), 0) -> 148516.5 | I12: =_xlfn.ISOWEEKNUM(A12) -> 22 | J12: =TEXT(A12,"yyyy-mm-dd") & TRIM(B12) -> 2020-05-26Кемерово
A13: 43952 | B13: Кемерово | C13: 32487 | D13: 3031254 | E13: =IFERROR(VLOOKUP(J13,Sheet2!C13:F516,2),0) -> 18 | F13: =IFERROR(VLOOKUP(J13,Sheet2!C13:F516,3),0) -> 1826 | G13: =IFERROR(VLOOKUP(J13, Sheet2!C13:F516,4),0) -> 1633 | H13: =IF(VALUE(E13)>0, D13/VALUE(E13), 0) -> 168403 | I13: =_xlfn.ISOWEEKNUM(A13) -> 18 | J13: =TEXT(A13,"yyyy-mm-dd") & TRIM(B13) -> 2020-05-01Кемерово
... A504: 43980 | B504: Новосибирск | C504: 16878 | D504: 1438255.5 | E504: =IFERROR(VLOOKUP(J504,Sheet2!C504:F1007,2),0) -> 0 | F504: =IFERROR(VLOOKUP(J504,Sheet2!C504:F1007,3),0) -> 0 | G504: =IFERROR(VLOOKUP(J504, Sheet2!C504:F1007,4),0) -> 0 | H504: =IF(VALUE(E504)>0, D504/VALUE(E504), 0) -> 0 | I504: =_xlfn.ISOWEEKNUM(A504) -> 22 | J504: =TEXT(A504,"yyyy-mm-dd") & TRIM(B504) -> 2020-05-29Новосибирск
A505: 43983 | B505: Новосибирск | C505: 14238 | D505: 1293219 | E505: =IFERROR(VLOOKUP(J505,Sheet2!C505:F1008,2),0) -> 0 | F505: =IFERROR(VLOOKUP(J505,Sheet2!C505:F1008,3),0) -> 0 | G505: =IFERROR(VLOOKUP(J505, Sheet2!C505:F1008,4),0) -> 0 | H505: =IF(VALUE(E505)>0, D505/VALUE(E505), 0) -> 0 | I505: =_xlfn.ISOWEEKNUM(A505) -> 23

Sheet Sheet2
A1: Дата | B1: Территория | D1: Количество складов | E1: Количество заказов | F1: Количество клиентов
A2: 43949 | B2: Волгоград | C2: 2020-04-28Волгоград | D2: 36 | E2: 4923 | F2: 4560 | G2: =TEXT(A2,"yyyy-mm-dd") & TRIM(B2) -> 2020-04-28Волгоград
A3: 43949 | B3: Екатеринбург | C3: 2020-04-28Екатеринбург | D3: 31 | E3: 5465 | F3: 5096 | G3: =TEXT(A3,"yyyy-mm-dd") & TRIM(B3) -> 2020-04-28Екатеринбург
A4: 43949 | B4: Казань | C4: 2020-04-28Казань | D4: 19 | E4: 1846 | F4: 1681 | G4: =TEXT(A4,"yyyy-mm-dd") & TRIM(B4) -> 2020-04-28Казань
A5: 43949 | B5: Кемерово | C5: 2020-04-28Кемерово | D5: 18 | E5: 1539 | F5: 1404 | G5: =TEXT(A5,"yyyy-mm-dd") & TRIM(B5) -> 2020-04-28Кемерово
A6: 43949 | B6: Краснодар | C6: 2020-04-28Краснодар | D6: 18 | E6: 1505 | F6: 1368 | G6: =TEXT(A6,"yyyy-mm-dd") & TRIM(B6) -> 2020-04-28Краснодар
A7: 43949 | B7: Москва Восток | C7: 2020-04-28Москва Восток | D7: 54 | E7: 12306 | F7: 11532 | G7: =TEXT(A7,"yyyy-mm-dd") & TRIM(B7) -> 2020-04-28Москва Восток
A8: 43949 | B8: Москва Запад | C8: 2020-04-28Москва Запад | D8: 59 | E8: 12943 | F8: 12072 | G8: =TEXT(A8,"yyyy-mm-dd") & TRIM(B8) -> 2020-04-28Москва Запад
A9: 43949 | B9: Нижний Новгород | C9: 2020-04-28Нижний Новгород | D9: 17 | E9: 1439 | F9: 1265 | G9: =TEXT(A9,"yyyy-mm-dd") & TRIM(B9) -> 2020-04-28Нижний Новгород
A10: 43949 | B10: Новосибирск | C10: 2020-04-28Новосибирск | D10: 15 | E10: 636 | F10: 547 | G10: =TEXT(A10,"yyyy-mm-dd") & TRIM(B10) -> 2020-04-28Новосибирск
A11: 43949 | B11: Пермь | C11: 2020-04-28Пермь | D11: 15 | E11: 780 | F11: 690 | G11: =TEXT(A11,"yyyy-mm-dd") & TRIM(B11) -> 2020-04-28Пермь
A12: 43949 | B12: Санкт-Петербург Север | C12: 2020-04-28Санкт-Петербург Север | D12: 125 | E12: 20914 | F12: 19479 | G12: =TEXT(A12,"yyyy-mm-dd") & TRIM(B12) -> 2020-04-28Санкт-Петербург Север
A13: 43949 | B13: Санкт-Петербург Юг | C13: 2020-04-28Санкт-Петербург Юг | D13: 128 | E13: 16450 | F13: 15320 | G13: =TEXT(A13,"yyyy-mm-dd") & TRIM(B13) -> 2020-04-28Санкт-Петербург Юг
... A505: 43983 | B505: Уфа | C505: 2020-06-01Уфа | D505: 6 | E505: 237 | F505: 175 | G505: =TEXT(A505,"yyyy-mm-dd") & TRIM(B505) -> 2020-06-01Уфа

Sheet Last_week
B3: Column Labels
A4: Row Labels | B4: 23 | C4: Grand Total
A5: Sum of Товарооборот, руб
A6: Волгоград | B6: 5800290 | C6: 5800290
A7: Екатеринбург | B7: 6829921.5 | C7: 6829921.5
A8: Казань | B8: 3865251 | C8: 3865251
A9: Кемерово | B9: 2945035.5 | C9: 2945035.5
A10: Краснодар | B10: 2538967.5 | C10: 2538967.5
A11: Москва Восток | B11: 18914194 | C11: 18914194
A12: Москва Запад | B12: 19465372 | C12: 19465372
A13: Нижний Новгород | B13: 3013512 | C13: 3013512
A14: Новосибирск | B14: 1293219 | C14: 1293219
A15: Пермь | B15: 1526608.5 | C15: 1526608.5
A16: Ростов-на-Дону | B16: 1565632.5 | C16: 1565632.5
A17: Самара | B17: 636345 | C17: 636345
... A23: Уфа | B23: 410892 | C23: 410892
A24: Sum of Товарооборот на склад
A25: Волгоград | B25: 156764.59 | C25: 156764.59
A26: Екатеринбург | B26: 220320.05 | C26: 220320.05
A27: Казань | B27: 168054.39 | C27: 168054.39
A28: Кемерово | B28: 140239.79 | C28: 140239.79
A29: Краснодар | B29: 120903.21 | C29: 120903.21
A30: Москва Восток | B30: 350262.86 | C30: 350262.86
A31: Москва Запад | B31: 329921.57 | C31: 329921.57
A32: Нижний Новгород | B32: 150675.6 | C32: 150675.6
A33: Новосибирск | B33: 0 | C33: 0
A34: Пермь | B34: 89800.5 | C34: 89800.5
A35: Ростов-на-Дону | B35: 97852.031 | C35: 97852.031
A36: Самара | B36: 42423 | C36: 42423
... A44: Total Sum of Товарооборот на склад | B44: 2714195.9 | C44: 2714195.9

Sheet Sheet9
A3: Row Labels | B3: Sum of Товарооборот, руб | C3: Count of Товарооборот на склад
A4: 18 | B4: 836803032 | C4: 82
A5: 19 | B5: 9.8391541e+08 | C5: 98
A6: 20 | B6: 9.4726301e+08 | C6: 98
A7: 21 | B7: 1.0026919e+09 | C7: 98
A8: 22 | B8: 1.0556535e+09 | C8: 110
A9: 23 | B9: 1.3603238e+08 | C9: 18
A10: Grand Total | B10: 4.9623592e+09 | C10: #N/A

Sheet Sheet4
A3: Row Labels | B3: Sum of Товарооборот, руб | C3: Count of Товарооборот на склад
A4: 23 | B4: 1.3603238e+08 | C4: 18
A5: Волгоград | B5: 5800290 | C5: 1
A6: Екатеринбург | B6: 6829921.5 | C6: 1
A7: Казань | B7: 3865251 | C7: 1
A8: Кемерово | B8: 2945035.5 | C8: 1
A9: Краснодар | B9: 2538967.5 | C9: 1
A10: Москва Восток | B10: 18914194 | C10: 1
A11: Москва Запад | B11: 19465372 | C11: 1
A12: Нижний Новгород | B12: 3013512 | C12: 1
A13: Новосибирск | B13: 1293219 | C13: 1
A14: Пермь | B14: 1526608.5 | C14: 1
A15: Ростов-на-Дону | B15: 1565632.5 | C15: 1
A16: Самара | B16: 636345 | C16: 1
... A23: Grand Total | B23: 1.3603238e+08 | C23: 18

Sheet Detail2
A1: Details for Sum of Товарооборот на склад
A3: Дата | B3: Территория | C3: Товарооборот, шт | D3: Товарооборот, руб | E3: Количество складов | F3: Количество заказов | G3: Количество клиентов | H3: Товарооборот на склад | I3: Неделя
A4: 43950 | B4: Кемерово | C4: 29319 | D4: 2623480.5 | E4: 18 | F4: 1684 | G4: 1528 | H4: 145748.92 | I4: 18
A5: 43953 | B5: Кемерово | C5: 29031 | D5: 2711247 | E5: 18 | F5: 1708 | G5: 1534 | H5: 150624.83 | I5: 18
A6: 43952 | B6: Кемерово | C6: 32487 | D6: 3031254 | E6: 18 | F6: 1826 | G6: 1633 | H6: 168403 | I6: 18
A7: 43949 | B7: Кемерово | C7: 26940 | D7: 2411587.5 | E7: #N/A | F7: #N/A | G7: #N/A | H7: 0 | I7: 18
A8: 43954 | B8: Кемерово | C8: 26082 | D8: 2434914 | E8: 20 | F8: 1520 | G8: 1373 | H8: 121745.7 | I8: 18
A9: 43951 | B9: Кемерово | C9: 30445.5 | D9: 2817196.5 | E9: 19 | F9: 1712 | G9: 1552 | H9: 148273.5 | I9: 18
A10: 43950 | B10: Екатеринбург | C10: 79527 | D10: 7180498.5 | E10: #N/A | F10: #N/A | G10: #N/A | H10: 0 | I10: 18
A11: 43953 | B11: Екатеринбург | C11: 60463.5 | D11: 5554192.5 | E11: 31 | F11: 4157 | G11: 3823 | H11: 179167.5 | I11: 18
A12: 43952 | B12: Екатеринбург | C12: 97534.5 | D12: 8893024.5 | E12: 31 | F12: 6118 | G12: 5564 | H12: 286871.76 | I12: 18
A13: 43949 | B13: Екатеринбург | C13: 81826.5 | D13: 7163644.5 | E13: #N/A | F13: #N/A | G13: #N/A | H13: 0 | I13: 18
A14: 43954 | B14: Екатеринбург | C14: 77263.5 | D14: 7013670 | E14: 31 | F14: 5155 | G14: 4762 | H14: 226247.42 | I14: 18
A15: 43951 | B15: Екатеринбург | C15: 77565 | D15: 7023727.5 | E15: #N/A | F15: #N/A | G15: #N/A | H15: 0 | I15: 18
A16: 43950 | B16: Тольятти | C16: 10840.5 | D16: 797919 | E16: #N/A | F16: #N/A | G16: #N/A | H16: 0 | I16: 18
A17: 43953 | B17: Тольятти | C17: 7866 | D17: 617881.5 | E17: 10 | F17: 416 | G17: 341 | H17: 61788.15 | I17: 18
A18: 43952 | B18: Тольятти | C18: 11619 | D18: 891139.5 | E18: #N/A | F18: #N/A | G18: #N/A | H18: 0 | I18: 18
A19: 43949 | B19: Тольятти | C19: 12331.5 | D19: 869983.5 | E19: #N/A | F19: #N/A | G19: #N/A | H19: 0 | I19: 18
A20: 43954 | B20: Тольятти | C20: 8185.5 | D20: 637881 | E20: 10 | F20: 402 | G20: 333 | H20: 63788.1 | I20: 18
A21: 43951 | B21: Тольятти | C21: 8934 | D21: 716196 | E21: #N/A | F21: #N/A | G21: #N/A | H21: 0 | I21: 18
A22: 43950 | B22: Нижний Новгород | C22: 25917 | D22: 2397588 | E22: #N/A | F22: #N/A | G22: #N/A | H22: 0 | I22: 18
A23: 43953 | B23: Нижний Новгород | C23: 19461 | D23: 1799230.5 | E23: #N/A | F23: #N/A | G23: #N/A | H23: 0 | I23: 18
A24: 43952 | B24: Нижний Новгород | C24: 25792.5 | D24: 2374356 | E24: #N/A | F24: #N/A | G24: #N/A | H24: 0 | I24: 18
A25: 43949 | B25: Нижний Новгород | C25: 23314.5 | D25: 2136817.5 | E25: #N/A | F25: #N/A | G25: #N/A | H25: 0 | I25: 18
A26: 43954 | B26: Нижний Новгород | C26: 23539.5 | D26: 2170309.5 | E26: #N/A | F26: #N/A | G26: #N/A | H26: 0 | I26: 18
A27: 43951 | B27: Нижний Новгород | C27: 24211.5 | D27: 2267664 | E27: #N/A | F27: #N/A | G27: #N/A | H27: 0 | I27: 18
A28: 43950 | B28: Санкт-Петербург Юг | C28: 298059 | D28: 30869288 | E28: #N/A | F28: #N/A | G28: #N/A | H28: 0 | I28: 18
A29: 43953 | B29: Санкт-Петербург Юг | C29: 232903.5 | D29: 24342016 | E29: #N/A | F29: #N/A | G29: #N/A | H29: 0 | I29: 18
A30: 43952 | B30: Санкт-Петербург Юг | C30: 296149.5 | D30: 31053316 | E30: #N/A | F30: #N/A | G30: #N/A | H30: 0 | I30: 18
A31: 43949 | B31: Санкт-Петербург Юг | C31: 286002 | D31: 29159032 | E31: #N/A | F31: #N/A | G31: #N/A | H31: 0 | I31: 18
A32: 43954 | B32: Санкт-Петербург Юг | C32: 274083 | D32: 28427001 | E32: #N/A | F32: #N/A | G32: #N/A | H32: 0 | I32: 18
... A85: 43951 | B85: Новосибирск | C85: 11976 | D85: 1004511 | E85: #N/A | F85: #N/A | G85: #N/A | H85: 0 | I85: 18
A86: 43960 | B86: Кемерово | C86: 31147.5 | D86: 2831019 | E86: 21 | F86: 1735 | G86: 1568 | H86: 134810.43 | I86: 19
A87: 43955 | B87: Кемерово | C87: 25566 | D87: 2372310 | E87: 20 | F87: 1519 | G87: 1372 | H87: 118615.5 | I87: 19
A88: 43956 | B88: Кемерово | C88: 31566 | D88: 2906763 | E88: 20 | F88: 1773 | G88: 1604 | H88: 145338.15 | I88: 19
A89: 43957 | B89: Кемерово | C89: 32511 | D89: 2938623 | E89: 20 | F89: 1784 | G89: 1632 | H89: 146931.15 | I89: 19
A90: 43961 | B90: Кемерово | C90: 36619.5 | D90: 3312967.5 | E90: 21 | F90: 2016 | G90: 1846 | H90: 157760.36 | I90: 19
A91: 43959 | B91: Кемерово | C91: 29409 | D91: 2645160 | E91: 21 | F91: 1646 | G91: 1492 | H91: 125960 | I91: 19
A92: 43958 | B92: Кемерово | C92: 27018 | D92: 2472213 | E92: 21 | F92: 1542 | G92: 1405 | H92: 117724.43 | I92: 19
A93: 43960 | B93: Екатеринбург | C93: 69720 | D93: 6264933 | E93: 31 | F93: 4556 | G93: 4220 | H93: 202094.61 | I93: 19
...

Sheet Detail1
A1: Details for Count of Товарооборот на склад
A3: Дата | B3: Территория | C3: Товарооборот, шт | D3: Товарооборот, руб | E3: Количество складов | F3: Количество заказов | G3: Количество клиентов | H3: Товарооборот на склад | I3: Неделя
A4: 43950 | B4: Кемерово | C4: 29319 | D4: 2623480.5 | E4: 18 | F4: 1684 | G4: 1528 | H4: 145748.92 | I4: 18
A5: 43953 | B5: Кемерово | C5: 29031 | D5: 2711247 | E5: 18 | F5: 1708 | G5: 1534 | H5: 150624.83 | I5: 18
A6: 43952 | B6: Кемерово | C6: 32487 | D6: 3031254 | E6: 18 | F6: 1826 | G6: 1633 | H6: 168403 | I6: 18
A7: 43949 | B7: Кемерово | C7: 26940 | D7: 2411587.5 | E7: #N/A | F7: #N/A | G7: #N/A | H7: #N/A | I7: 18
A8: 43954 | B8: Кемерово | C8: 26082 | D8: 2434914 | E8: 20 | F8: 1520 | G8: 1373 | H8: 121745.7 | I8: 18
A9: 43951 | B9: Кемерово | C9: 30445.5 | D9: 2817196.5 | E9: 19 | F9: 1712 | G9: 1552 | H9: 148273.5 | I9: 18
A10: 43950 | B10: Екатеринбург | C10: 79527 | D10: 7180498.5 | E10: #N/A | F10: #N/A | G10: #N/A | H10: #N/A | I10: 18
A11: 43953 | B11: Екатеринбург | C11: 60463.5 | D11: 5554192.5 | E11: 31 | F11: 4157 | G11: 3823 | H11: 179167.5 | I11: 18
A12: 43952 | B12: Екатеринбург | C12: 97534.5 | D12: 8893024.5 | E12: 31 | F12: 6118 | G12: 5564 | H12: 286871.76 | I12: 18
A13: 43949 | B13: Екатеринбург | C13: 81826.5 | D13: 7163644.5 | E13: #N/A | F13: #N/A | G13: #N/A | H13: #N/A | I13: 18
A14: 43954 | B14: Екатеринбург | C14: 77263.5 | D14: 7013670 | E14: 31 | F14: 5155 | G14: 4762 | H14: 226247.42 | I14: 18
A15: 43951 | B15: Екатеринбург | C15: 77565 | D15: 7023727.5 | E15: #N/A | F15: #N/A | G15: #N/A | H15: #N/A | I15: 18
A16: 43950 | B16: Тольятти | C16: 10840.5 | D16: 797919 | E16: #N/A | F16: #N/A | G16: #N/A | H16: #N/A | I16: 18
A17: 43953 | B17: Тольятти | C17: 7866 | D17: 617881.5 | E17: 10 | F17: 416 | G17: 341 | H17: 61788.15 | I17: 18
A18: 43952 | B18: Тольятти | C18: 11619 | D18: 891139.5 | E18: #N/A | F18: #N/A | G18: #N/A | H18: #N/A | I18: 18
A19: 43949 | B19: Тольятти | C19: 12331.5 | D19: 869983.5 | E19: #N/A | F19: #N/A | G19: #N/A | H19: #N/A | I19: 18
A20: 43954 | B20: Тольятти | C20: 8185.5 | D20: 637881 | E20: 10 | F20: 402 | G20: 333 | H20: 63788.1 | I20: 18
A21: 43951 | B21: Тольятти | C21: 8934 | D21: 716196 | E21: #N/A | F21: #N/A | G21: #N/A | H21: #N/A | I21: 18
A22: 43950 | B22: Нижний Новгород | C22: 25917 | D22: 2397588 | E22: #N/A | F22: #N/A | G22: #N/A | H22: #N/A | I22: 18
A23: 43953 | B23: Нижний Новгород | C23: 19461 | D23: 1799230.5 | E23: #N/A | F23: #N/A | G23: #N/A | H23: #N/A | I23: 18
A24: 43952 | B24: Нижний Новгород | C24: 25792.5 | D24: 2374356 | E24: #N/A | F24: #N/A | G24: #N/A | H24: #N/A | I24: 18
A25: 43949 | B25: Нижний Новгород | C25: 23314.5 | D25: 2136817.5 | E25: #N/A | F25: #N/A | G25: #N/A | H25: #N/A | I25: 18
A26: 43954 | B26: Нижний Новгород | C26: 23539.5 | D26: 2170309.5 | E26: #N/A | F26: #N/A | G26: #N/A | H26: #N/A | I26: 18
A27: 43951 | B27: Нижний Новгород | C27: 24211.5 | D27: 2267664 | E27: #N/A | F27: #N/A | G27: #N/A | H27: #N/A | I27: 18
A28: 43950 | B28: Санкт-Петербург Юг | C28: 298059 | D28: 30869288 | E28: #N/A | F28: #N/A | G28: #N/A | H28: #N/A | I28: 18
A29: 43953 | B29: Санкт-Петербург Юг | C29: 232903.5 | D29: 24342016 | E29: #N/A | F29: #N/A | G29: #N/A | H29: #N/A | I29: 18
A30: 43952 | B30: Санкт-Петербург Юг | C30: 296149.5 | D30: 31053316 | E30: #N/A | F30: #N/A | G30: #N/A | H30: #N/A | I30: 18
A31: 43949 | B31: Санкт-Петербург Юг | C31: 286002 | D31: 29159032 | E31: #N/A | F31: #N/A | G31: #N/A | H31: #N/A | I31: 18
A32: 43954 | B32: Санкт-Петербург Юг | C32: 274083 | D32: 28427001 | E32: #N/A | F32: #N/A | G32: #N/A | H32: #N/A | I32: 18
... A85: 43951 | B85: Новосибирск | C85: 11976 | D85: 1004511 | E85: #N/A | F85: #N/A | G85: #N/A | H85: #N/A | I85: 18
A86: 43960 | B86: Кемерово | C86: 31147.5 | D86: 2831019 | E86: 21 | F86: 1735 | G86: 1568 | H86: 134810.43 | I86: 19
A87: 43955 | B87: Кемерово | C87: 25566 | D87: 2372310 | E87: 20 | F87: 1519 | G87: 1372 | H87: 118615.5 | I87: 19
A88: 43956 | B88: Кемерово | C88: 31566 | D88: 2906763 | E88: 20 | F88: 1773 | G88: 1604 | H88: 145338.15 | I88: 19
A89: 43957 | B89: Кемерово | C89: 32511 | D89: 2938623 | E89: 20 | F89: 1784 | G89: 1632 | H89: 146931.15 | I89: 19
A90: 43961 | B90: Кемерово | C90: 36619.5 | D90: 3312967.5 | E90: 21 | F90: 2016 | G90: 1846 | H90: 157760.36 | I90: 19
A91: 43959 | B91: Кемерово | C91: 29409 | D91: 2645160 | E91: 21 | F91: 1646 | G91: 1492 | H91: 125960 | I91: 19
A92: 43958 | B92: Кемерово | C92: 27018 | D92: 2472213 | E92: 21 | F92: 1542 | G92: 1405 | H92: 117724.43 | I92: 19
A93: 43960 | B93: Екатеринбург | C93: 69720 | D93: 6264933 | E93: 31 | F93: 4556 | G93: 4220 | H93: 202094.61 | I93: 19
...
